mevemon    DEBUG Logging successfully set-up.
/home/mothra/Projects/desktop-mevemon/ui/linux/gui.py:44: DeprecationWarning: use gtk.UIManager
  item_factory = gtk.ItemFactory(gtk.MenuBar,"<main>", accel_group)
mevemon    ERROR Failed to get character list
Traceback (most recent call last):
  File "./mevemon.py", line 177, in get_chars_from_acct
    api_char_list = auth.account.Characters()
  File "/home/mothra/Projects/desktop-mevemon/eveapi/eveapi.py", line 233, in __call__
    return self._root(self._path, **kw)
  File "/home/mothra/Projects/desktop-mevemon/eveapi/eveapi.py", line 306, in __call__
    return _ParseXML(response, True, store and (lambda obj: cache.store(self._host, path, kw, response, obj)))
  File "/home/mothra/Projects/desktop-mevemon/eveapi/eveapi.py", line 169, in _ParseXML
    raise Error(error.code, error.data)
Error: Unexpected failure accessing database
mevemon    ERROR Failed to get character list
Traceback (most recent call last):
  File "./mevemon.py", line 177, in get_chars_from_acct
    api_char_list = auth.account.Characters()
  File "/home/mothra/Projects/desktop-mevemon/eveapi/eveapi.py", line 233, in __call__
    return self._root(self._path, **kw)
  File "/home/mothra/Projects/desktop-mevemon/eveapi/eveapi.py", line 306, in __call__
    return _ParseXML(response, True, store and (lambda obj: cache.store(self._host, path, kw, response, obj)))
  File "/home/mothra/Projects/desktop-mevemon/eveapi/eveapi.py", line 169, in _ParseXML
    raise Error(error.code, error.data)
Error: Unexpected failure accessing database
mevemon    ERROR Failed to get character list
Traceback (most recent call last):
  File "./mevemon.py", line 177, in get_chars_from_acct
    api_char_list = auth.account.Characters()
  File "/home/mothra/Projects/desktop-mevemon/eveapi/eveapi.py", line 233, in __call__
    return self._root(self._path, **kw)
  File "/home/mothra/Projects/desktop-mevemon/eveapi/eveapi.py", line 306, in __call__
    return _ParseXML(response, True, store and (lambda obj: cache.store(self._host, path, kw, response, obj)))
  File "/home/mothra/Projects/desktop-mevemon/eveapi/eveapi.py", line 169, in _ParseXML
    raise Error(error.code, error.data)
Error: Unexpected failure accessing database
mevemon    ERROR Uncaught exception:
Traceback (most recent call last):
  File "./mevemon.py", line 350, in <module>
    app = mEveMon()
  File "./mevemon.py", line 78, in __init__
    self.gui.run()
  File "/home/mothra/Projects/desktop-mevemon/ui/linux/gui.py", line 265, in run
    self.char_model = models.CharacterListModel(self.controller)
  File "/home/mothra/Projects/desktop-mevemon/ui/models.py", line 40, in __init__
    self.get_characters()
  File "/home/mothra/Projects/desktop-mevemon/ui/models.py", line 49, in get_characters
    self.set(liter, self.C_PORTRAIT, self._set_pix(icon), self.C_NAME, name, self.C_UID, uid)
  File "/home/mothra/Projects/desktop-mevemon/ui/models.py", line 52, in _set_pix
    pixbuf = gtk.gdk.pixbuf_new_from_file(filename)
GError: Failed to open file '/usr/share/mevemon/imgs/error.jpg': No such file or directory
